<?xml version="1.0" encoding="utf-8"?>
<!-- This URDF was automatically created by SolidWorks to URDF Exporter! Originally created by Stephen Brawner (brawner@gmail.com) 
     Commit Version: 1.6.0-1-g15f4949  Build Version: 1.6.7594.29634
     For more information, please see http://wiki.ros.org/sw_urdf_exporter -->
<robot
  name="v73">
  <link
    name="base_link">
    <inertial>
      <origin
        xyz="-6.81488676239284E-08 -2.52771949068807E-05 0.0421574765285959"
        rpy="0 0 0" />
      <mass
        value="0.126528900342696" />
      <inertia
        ixx="0.00023645920808511"
        ixy="-2.96508255106793E-10"
        ixz="4.22447214171758E-12"
        iyy="0.000186038701581783"
        iyz="1.18684222600256E-07"
        izz="0.000248653814949551" />
    </inertial>
    <visual>
      <origin
        xyz="0 0 0"
        rpy="0 0 0" />
      <geometry>
        <mesh
          filename="package://v73/meshes/base_link.STL" />
      </geometry>
      <material
        name="">
        <color
          rgba="0.752941176470588 0.752941176470588 0.752941176470588 1" />
      </material>
    </visual>
    <collision>
      <origin
        xyz="0 0 0"
        rpy="0 0 0" />
      <geometry>
        <mesh
          filename="package://v73/meshes/base_link.STL" />
      </geometry>
    </collision>
  </link>
  <link
    name="1_Link">
    <inertial>
      <origin
        xyz=" -0.0000   -0.0034    0.0773"
        rpy="0 0 0" />
      <mass
        value="1.2186" />
      <inertia
        ixx="  0.0013"
        ixy="     0.0000"
        ixz="    -0.0000"
        iyy="     0.0014"
        iyz="    -0.0007"
        izz="     0.0009"/>
    </inertial>
    <visual>
      <origin
        xyz="0 0 0"
        rpy="0 0 0" />
      <geometry>
        <mesh
          filename="package://v73/meshes/j1_Link.STL" />
      </geometry>
      <material
        name="">
        <color
          rgba="0.752941176470588 0.752941176470588 0.752941176470588 1" />
      </material>
    </visual>
    <collision>
      <origin
        xyz="0 0 0"
        rpy="0 0 0" />
      <geometry>
        <mesh
          filename="package://v73/meshes/j1_Link.STL" />
      </geometry>
    </collision>
  </link>
  <joint
    name="1_name"
    type="continuous">
    <origin
      xyz="0 0 0.08450000000001"
      rpy="0 0 0" />
    <parent
      link="base_link" />
    <child
      link="1_Link" />
    <axis
      xyz="0 0 1" />
  </joint>
  <link
    name="2_Link">
    <inertial>
      <origin
        xyz="-0.0000   -0.0220    0.0920"
        rpy="0 0 0" />
      <mass
        value="1.3974" />
      <inertia
        ixx="0.0031"
        ixy="    0.0000"
        ixz="   -0.0000"
        iyy="    0.0026"
        iyz="   -0.0064"
        izz="    0.0015"/>
    </inertial>
    <visual>
      <origin
        xyz="0 0 0"
        rpy="0 0 0" />
      <geometry>
        <mesh
          filename="package://v73/meshes/j2_Link.STL" />
      </geometry>
      <material
        name="">
        <color
          rgba="0.752941176470588 0.752941176470588 0.752941176470588 1" />
      </material>
    </visual>
    <collision>
      <origin
        xyz="0 0 0"
        rpy="0 0 0" />
      <geometry>
        <mesh
          filename="package://v73/meshes/j2_Link.STL" />
      </geometry>
    </collision>
  </link>
  <joint
    name="2_name"
    type="continuous">
    <origin
      xyz="0 0.02750000000001 0.08399999999909"
      rpy="0 0 0" />
    <parent
      link="1_Link" />
    <child
      link="2_Link" />
    <axis
      xyz="0 1 0" />
  </joint>
  <link
    name="3_Link">
    <inertial>
      <origin
        xyz="-0.0000    0.0034    0.0776"
        rpy="0 0 0" />
      <mass
        value="1.2186" />
      <inertia
        ixx=" 0.0013"
        ixy="   -0.0000"
        ixz="   -0.0000"
        iyy="    0.0014"
        iyz="    0.0007"
        izz="    0.0009"/>
    </inertial>
    <visual>
      <origin
        xyz="0 0 0"
        rpy="0 0 0" />
      <geometry>
        <mesh
          filename="package://v73/meshes/j3_Link.STL" />
      </geometry>
      <material
        name="">
        <color
          rgba="0.752941176470588 0.752941176470588 0.752941176470588 1" />
      </material>
    </visual>
    <collision>
      <origin
        xyz="0 0 0"
        rpy="0 0 0" />
      <geometry>
        <mesh
          filename="package://v73/meshes/j3_Link.STL" />
      </geometry>
    </collision>
  </link>
  <joint
    name="3_name"
    type="continuous">
    <origin
      xyz="0 -0.0325 0.1375000000001"
      rpy="0 0 0" />
    <parent
      link="2_Link" />
    <child
      link="3_Link" />
    <axis
      xyz="0 0 1" />
  </joint>
  <link
    name="4_Link">
    <inertial>
      <origin
        xyz=" 0.0000   -0.0145    0.0918"
        rpy="0 0 0" />
      <mass
        value="0.9495" />
      <inertia
        ixx=" 0.0025"
        ixy="   -0.0000"
        ixz="    0.0000"
        iyy="    0.0022"
        iyz="   -0.0032"
        izz="    0.0008"/>
    </inertial>
    <visual>
      <origin
        xyz="0 0 0"
        rpy="0 0 0" />
      <geometry>
        <mesh
          filename="package://v73/meshes/j4_Link.STL" />
      </geometry>
      <material
        name="">
        <color
          rgba="0.752941176470588 0.752941176470588 0.752941176470588 1" />
      </material>
    </visual>
    <collision>
      <origin
        xyz="0 0 0"
        rpy="0 0 0" />
      <geometry>
        <mesh
          filename="package://v73/meshes/j4_Link.STL" />
      </geometry>
    </collision>
  </link>
  <joint
    name="4_name"
    type="continuous">
    <origin
      xyz="0 -0.0275000000002227 0.0839999999998857"
      rpy="0 0 0" />
    <parent
      link="3_Link" />
    <child
      link="4_Link" />
    <axis
      xyz="0 -1 0" />
  </joint>
  <link
    name="5_Link">
    <inertial>
      <origin
        xyz=" 0.0000    0.0029    0.0702"
        rpy="0 0 0" />
      <mass
        value="0.7731" />
      <inertia
        ixx="0.6862e-03"
        ixy="   -0.0007e-03"
        ixz="    0.0046e-03"
        iyy="    0.7288e-03"
        iyz="    0.3396e-03"
        izz="    0.3928e-03"/>
    </inertial>
    <visual>
      <origin
        xyz="0 0 0"
        rpy="0 0 0" />
      <geometry>
        <mesh
          filename="package://v73/meshes/j5_Link.STL" />
      </geometry>
      <material
        name="">
        <color
          rgba="0.752941176470588 0.752941176470588 0.752941176470588 1" />
      </material>
    </visual>
    <collision>
      <origin
        xyz="0 0 0"
        rpy="0 0 0" />
      <geometry>
        <mesh
          filename="package://v73/meshes/j5_Link.STL" />
      </geometry>
    </collision>
  </link>
  <joint
    name="5_name"
    type="continuous">
    <origin
      xyz="0 0.0275000000001797 0.138996210594914"
      rpy="0 0 0" />
    <parent
      link="4_Link" />
    <child
      link="5_Link" />
    <axis
      xyz="0 0 1" />
  </joint>
  <link
    name="6_Link">
    <inertial>
      <origin
        xyz=" 0.0000   -0.0174    0.0848"
        rpy="0 0 0" />
      <mass
        value="0.8716" />
      <inertia
        ixx=" 0.0016"
        ixy="   -0.0000"
        ixz="    0.0000"
        iyy="    0.0014"
        iyz="   -0.0030"
        izz="    0.0007" />
    </inertial>
    <visual>
      <origin
        xyz="0 0 0"
        rpy="0 0 0" />
      <geometry>
        <mesh
          filename="package://v73/meshes/j6_Link.STL" />
      </geometry>
      <material
        name="">
        <color
          rgba="0.752941176470588 0.752941176470588 0.752941176470588 1" />
      </material>
    </visual>
    <collision>
      <origin
        xyz="0 0 0"
        rpy="0 0 0" />
      <geometry>
        <mesh
          filename="package://v73/meshes/j6_Link.STL" />
      </geometry>
    </collision>
  </link>
  <joint
    name="6_name"
    type="continuous">
    <origin
      xyz="0 0.0275999999981546 0.0785000000013523"
      rpy="0 0 0" />
    <parent
      link="5_Link" />
    <child
      link="6_Link" />
    <axis
      xyz="0 1 0" />
  </joint>
  <link
    name="7_Link">
    <inertial>
      <origin
        xyz=" 0         0    0.0174"
        rpy="0 0 0" />
      <mass
        value="0.0846" />
      <inertia
        ixx="0.2513e-04"
        ixy="         0e-04"
        ixz="         0e-04"
        iyy="    0.2513e-04"
        iyz="         0e-04"
        izz="    0.2202e-04"/>
    </inertial>
    <visual>
      <origin
        xyz="0 0 0"
        rpy="0 0 0" />
      <geometry>
        <mesh
          filename="package://v73/meshes/j7_Link.STL" />
      </geometry>
      <material
        name="">
        <color
          rgba="0.752941176470588 0.752941176470588 0.752941176470588 1" />
      </material>
    </visual>
    <collision>
      <origin
        xyz="0 0 0"
        rpy="0 0 0" />
      <geometry>
        <mesh
          filename="package://v73/meshes/j7_Link.STL" />
      </geometry>
    </collision>
  </link>
  <joint
    name="7_name"
    type="continuous">
    <origin
      xyz="0 -0.0275999999991848 0.123599999999348"
      rpy="0 0 0" />
    <parent
      link="6_Link" />
    <child
      link="7_Link" />
    <axis
      xyz="0 0 1" />
  </joint>
</robot>